Workbook

Sheet 字段
A4: 支出 | B4: 货款
B5: 工程服务费 | C5: ：技术服务费、劳务费
B6: 费用 | C6: ：办公、管理、财务、利息、税费、员工报销、手续费、修理费、汽油费
B7: 税款 | C7: ：增值税、附加税
B8: 薪资社保福利 | C8: ：工资、福利、社保、公积金
B9: 往来款付款 | C9: ：借款、还款、保证金、押金
B10: 公司帐户互转出
B11: 备用金取现
A13: 收入 | B13: 工程款收入
B14: 销售货款收入
B15: 往来款收款 | C15: ：借入款、退保证金、押金
B16: 其它收入 | C16: ：补贴、…
B17: 备用金存入
B18: 公司帐户互转入

Sheet 2月银行帐汇总
A1: 2026年2月 银行流水统计
B2: 分类 | C2: 分类说明 | D2: 合计 | E2: 光大 | F2: 建行 | G2: 平安 | H2: 民生 | I2: 工行税户
A3: 2月 支出 | B3: 货款 | C3: 设备采购、材料费 | D3: =SUM(E3:I3) -> 0 | E3: =光大2月!D24 -> 0 | F3: =建行2月!C78 -> 0 | G3: =平安2月!C10 -> 0 | H3: =民生2月!D16 -> 0 | I3: =工行税户2月!C11 -> 0
B4: 工程服务费 | C4: 技术服务费、劳务费 | D4: =SUM(E4:I4) -> 46903.79 | E4: =光大2月!D25 -> 46903.79 | F4: =建行2月!C79 -> 0 | G4: =平安2月!C11 -> 0 | H4: =民生2月!D17 -> 0 | I4: =工行税户2月!C12 -> 0
B5: 费用 | C5: 办公、管理、财务、利息、员工报销、手续费、修理费、汽油费等 | D5: =SUM(E5:I5) -> 19321.87 | E5: =光大2月!D26 -> 0 | F5: =建行2月!C80 -> 12830.54 | G5: =平安2月!C12 -> 6459.33 | H5: =民生2月!D18 -> 32 | I5: =工行税户2月!C13 -> 0
B6: 税款 | C6: 增值税、附加税、企业所得税 | D6: =SUM(E6:I6) -> 3219.32 | E6: =光大2月!D27 -> 0 | F6: =建行2月!C81 -> 2500 | G6: =平安2月!C13 -> 0 | H6: =民生2月!D19 -> 0 | I6: =工行税户2月!C14 -> 719.32
B7: 薪资社保福利 | C7: 工资、福利、社保、公积金 | D7: =SUM(E7:I7) -> 224814.75 | E7: =光大2月!D28 -> 0 | F7: =建行2月!C82 -> 184597.25 | G7: =平安2月!C14 -> 0 | H7: =民生2月!D20 -> 0 | I7: =工行税户2月!C15 -> 40217.5
B8: 银行成本费用支出合计 | D8: =SUM(D3:D7) -> 294259.73
B9: 往来款付款 | C9: 借出款、还款、保证金、押金 | D9: =SUM(E9:I9) -> 6422076.9 | E9: =光大2月!D29 -> 5415208.3 | F9: =建行2月!C83 -> 6868.55 | G9: =平安2月!C15 -> 0 | H9: =民生2月!D21 -> 1000000 | I9: =工行税户2月!C16 -> 0
B10: 备用金取现 | D10: =SUM(E10:I10) -> 0 | E10: =光大2月!D30 -> 0 | F10: =建行2月!C84 -> 0 | G10: =平安2月!C16 -> 0 | H10: =民生2月!D22 -> 0 | I10: =工行税户2月!C17 -> 0
B11: 银行 流出 资金合计 | D11: =D8+D9+D10 -> 6716336.6
A13: 2月 收入 | B13: 工程款收入 | D13: =SUM(E13:I13) -> 241458.55 | E13: =光大2月!E36 -> 0 | F13: =建行2月!C90 -> 241458.55 | G13: =平安2月!C22 -> 0 | H13: =民生2月!D28 -> 0 | I13: =工行税户2月!C23 -> 0
B14: 销售货款收入 | D14: =SUM(E14:I14) -> 0 | E14: =光大2月!E37 -> 0 | F14: =建行2月!C91 -> 0 | G14: =平安2月!C23 -> 0 | H14: =民生2月!D29 -> 0 | I14: =工行税户2月!C24 -> 0
B15: 其它收入 | C15: 补贴、政策退费、利息等 | D15: =SUM(E15:I15) -> 0 | E15: =光大2月!E38 -> 0 | F15: =建行2月!C92 -> 0 | G15: =平安2月!C24 -> 0 | H15: =民生2月!D30 -> 0 | I15: =工行税户2月!C25 -> 0
B16: 银行收入合计 | D16: =SUM(D13:D15) -> 241458.55
B17: 备用金存入 | D17: =SUM(E17:I17) -> 0 | F17: =建行2月!C94 -> 0
B18: 往来款收款 | C18: 借入款、退保证金、押金、退款等 | D18: =SUM(E18:I18) -> 6960000.5 | E18: =光大2月!E39 -> 3000000 | F18: =建行2月!C93 -> 2960000.5 | G18: =平安2月!C25 -> 0 | H18: =民生2月!D31 -> 1000000 | I18: =工行税户2月!C26 -> 0
B19: 银行 流入 资金合计 | D19: =D16+D17+D18 -> 7201459
B21: 未统计公司各帐户之间转款金额

Sheet 建行2月
A1: 选择 | B1: 客户账号 | C1: 账户名称 | D1: 交易时间 | E1: 借方发生额（支取） | F1: 贷方发生额（收入） | G1: 余额 | H1: 币种 | I1: 对方户名 | J1: 对方账号 | K1: 对方开户机构 | L1: 记账日期 | M1: 摘要 | N1: 备注 | O1: 账户明细编号-交易流水号 | P1: 企业流水号 | Q1: 凭证种类 | R1: 凭证号码 | S1: 个性化信息名称1 | T1: 个性化信息名称2 | U1: 个性化信息名称3 | V1: 个性化信息名称4 | W1: 个性化信息名称5 | X1: 个性化信息名称6 | Y1: 个性化信息名称7 | Z1: 个性化信息名称8 | AA1: 个性化信息名称9 | AB1: 个性化信息名称10 | AC1: 个性化信息1 | AD1: 个性化信息2 | AE1: 个性化信息3 | AF1: 个性化信息4 | AG1: 个性化信息5 | AH1: 个性化信息6 | AI1: 个性化信息7 | AJ1: 个性化信息8 | AK1: 个性化信息9 | AL1: 个性化信息10 | AM1: 交易介质编号
A3: 往来款收款 | B3: 53001905038050548106 | C3: 云南溯源科技有限公司 | D3: 20260202 15:50:03 | E3: 0 | F3: 500000 | G3: 624077.96 | H3: 人民币元 | I3: 昆明康泽电子科技有限公司 | J3: 132071516010006050 | K3: 广发银行股份有限公司 | L3: 20260202 | M3: 电子汇入 | N3: 电子汇入 | O3: 13348-530085036F9FUSK564L | Q3: 电汇凭证
A4: 往来款收款 | B4: 53001905038050548106 | C4: 云南溯源科技有限公司 | D4: 20260203 08:24:01 | E4: 0 | F4: 100000 | G4: 724077.96 | H4: 人民币元 | I4: 房克丽 | J4: 6217681902921728 | K4: 中信银行总行管理部（不受理储蓄业务） | L4: 20260203 | M4: 电子汇入 | N4: 暂借款 | O4: 13349-5300850368436BUSRUE | Q4: 电汇凭证
A5: 往来款收款 | B5: 53001905038050548106 | C5: 云南溯源科技有限公司 | D5: 20260203 08:27:06 | E5: 0 | F5: 160000 | G5: 884077.96 | H5: 人民币元 | I5: 房克丽 | J5: 6212262502001128704 | K5: 中国工商银行总行清算中心 | L5: 20260203 | M5: 电子汇入 | N5: 电子汇入 | O5: 13350-5300850368565YWZ6GZ | Q5: 电汇凭证
A6: 往来款付款 | B6: 53001905038050548106 | C6: 云南溯源科技有限公司 | D6: 20260203 09:00:14 | E6: 6868.55 | F6: 0 | G6: 877209.41 | H6: 人民币元 | I6: 刘树刚 | J6: 6217003860012460901 | K6: 建行昆明景江花园支行 | L6: 20260203 | M6: 电子转账 | N6: 代购公车款 | O6: 13351-5309050388V2NP3WSAS | Q6: 电子转账凭证 | R6: 108159747969
A7: 往来款收款 | B7: 53001905038050548106 | C7: 云南溯源科技有限公司 | D7: 20260203 09:16:49 | E7: 0 | F7: 240000 | G7: 1117209.4 | H7: 人民币元 | I7: 刘涵静 | J7: 6214157312905917846 | K7: 富滇银行股份有限公司 | L7: 20260203 | M7: 电子汇入 | N7: 暂借款 | O7: 13352-53008503690VCMJ7OZR | Q7: 电汇凭证
A8: 费用 | B8: 53001905038050548106 | C8: 云南溯源科技有限公司 | D8: 20260203 09:49:50 | E8: 1 | F8: 0 | G8: 1117208.4 | H8: 人民币元 | L8: 20260203 | M8: 手续费 | N8: 对公人民币转账、汇款（含退汇）-跨行同城 | O8: 13353-5309050389CKJOCD8VE | Q8: 电子转账凭证 | R8: 108169477528
A9: 公司帐户互转出 | B9: 53001905038050548106 | C9: 云南溯源科技有限公司 | D9: 20260203 09:49:50 | E9: 500000 | F9: 0 | G9: 617208.41 | H9: 人民币元 | I9: 云南溯源科技有限公司 | J9: 39610188000598826 | K9: 中国光大银行昆明分行营业部 | L9: 20260203 | M9: 电子转账 | N9: 本公司帐户 | O9: 13354-5309050389CKJOCD8VE | Q9: 电子转账凭证 | R9: 108169477528
A10: 费用 | B10: 53001905038050548106 | C10: 云南溯源科技有限公司 | D10: 20260203 09:53:05 | E10: 1 | F10: 0 | G10: 617207.41 | H10: 人民币元 | L10: 20260203 | M10: 手续费 | N10: 对公人民币转账、汇款（含退汇）-跨行同城 | O10: 13355-5309050389DTU8XHHGI | Q10: 电子转账凭证 | R10: 108169482833
A11: 公司帐户互转出 | B11: 53001905038050548106 | C11: 云南溯源科技有限公司 | D11: 20260203 09:53:05 | E11: 500000 | F11: 0 | G11: 117207.41 | H11: 人民币元 | I11: 云南溯源科技有限公司 | J11: 39610188000598826 | K11: 中国光大银行昆明分行营业部 | L11: 20260203 | M11: 电子转账 | N11: 本公司帐户 | O11: 13356-5309050389DTU8XHHGI | Q11: 电子转账凭证 | R11: 108169482833
A12: 费用 | B12: 53001905038050548106 | C12: 云南溯源科技有限公司 | D12: 20260203 16:46:46 | E12: 1 | F12: 0 | G12: 117206.41 | H12: 人民币元 | L12: 20260203 | M12: 手续费 | N12: 对公人民币转账、汇款（含退汇）-跨行同城 | O12: 13357-530905038G7MHBEUAJX | Q12: 电子转账凭证 | R12: 108171405401
A13: 费用 | B13: 53001905038050548106 | C13: 云南溯源科技有限公司 | D13: 20260203 16:46:46 | E13: 3122 | F13: 0 | G13: 114084.41 | H13: 人民币元 | I13: 昆明奥宝汽车维修有限责任公司 | J13: 692568772 | K13: 中国民生银行股份有限公司昆明北京路支行 | L13: 20260203 | M13: 电子转账 | N13: 维修费 | O13: 13358-530905038G7MHBEUAJX | Q13: 电子转账凭证 | R13: 108171405401
A14: 往来款收款 | B14: 53001905038050548106 | C14: 云南溯源科技有限公司 | D14: 20260204 12:40:19 | E14: 0 | F14: 200000 | G14: 314084.41 | H14: 人民币元 | I14: 云南科裕腾科技有限责任公司 | J14: 39610188000409946 | K14: 中国光大银行昆明分行营业部 | L14: 20260204 | M14: 电子汇入 | N14: 往来款 | O14: 13359-530085036C7M007REMT | Q14: 电汇凭证
A15: 往来款收款 | B15: 53001905038050548106 | C15: 云南溯源科技有限公司 | D15: 20260204 13:20:48 | E15: 0 | F15: 200000 | G15: 514084.41 | H15: 人民币元 | I15: 贾小花 | J15: 6217003900007788112 | K15: 建行通海支行 | L15: 20260204 | M15: 转账存入 | N15: 暂借款 | O15: 13360-530085036D02MCQC5FB | AM15: 53001905038050548106
A16: 往来款收款 | B16: 53001905038050548106 | C16: 云南溯源科技有限公司 | D16: 20260204 13:23:17 | E16: 0 | F16: 200000 | G16: 714084.41 | H16: 人民币元 | I16: 梁秭涛 | J16: 6212262517001360313 | K16: 中国工商银行总行清算中心 | L16: 20260204 | M16: 电子汇入 | N16: 暂借款 | O16: 13361-530085036D10W7Y08HV | Q16: 电汇凭证
A17: 往来款收款 | B17: 53001905038050548106 | C17: 云南溯源科技有限公司 | D17: 20260204 14:41:51 | E17: 0 | F17: 400000 | G17: 1114084.4 | H17: 人民币元 | I17: 云南溯源科技有限公司 | J17: 53001090503850000002202545 | K17: 建行昆明金实支行 | L17: 20260204 | M17: 2408 | N17: 贷款53001090503850000002202545 | O17: 13362-530085036E6Z3YBH2MB
A18: 费用 | B18: 53001905038050548106 | C18: 云南溯源科技有限公司 | D18: 20260204 15:08:18 | E18: 1 | F18: 0 | G18: 1114083.4 | H18: 人民币元 | L18: 20260204 | M18: 手续费 | N18: 对公人民币转账、汇款（含退汇）-跨行同城 | O18: 13363-530905038EULVYNQSP5 | Q18: 电子转账凭证 | R18: 108173636112
A19: 公司帐户互转出 | B19: 53001905038050548106 | C19: 云南溯源科技有限公司 | D19: 20260204 15:08:18 | E19: 500000 | F19: 0 | G19: 614083.41 | H19: 人民币元 | I19: 云南溯源科技有限公司 | J19: 39610188000598826 | K19: 中国光大银行昆明分行营业部 | L19: 20260204 | M19: 电子转账 | N19: 本公司帐户 | O19: 13364-530905038EULVYNQSP5 | Q19: 电子转账凭证 | R19: 108173636112
A20: 费用 | B20: 53001905038050548106 | C20: 云南溯源科技有限公司 | D20: 20260204 15:10:44 | E20: 1090 | F20: 0 | G20: 612993.41 | H20: 人民币元 | I20: 安雨超 | J20: 6217007170002749362 | K20: 建行盘州市双凤支行 | L20: 20260204 | M20: 电子转账 | N20: 住宿费（红塔区友余宾馆） | O20: 13365-530905038EVEMMX7BUE | Q20: 电子转账凭证 | R20: 108173667357
A21: 费用 | B21: 53001905038050548106 | C21: 云南溯源科技有限公司 | D21: 20260204 15:17:45 | E21: 4.5 | F21: 0 | G21: 612988.91 | H21: 人民币元 | L21: 20260204 | M21: 手续费 | N21: 对公人民币转账、汇款（含退汇）-跨行异地 | O21: 13366-530905038EXW4669X9Y | Q21: 电子转账凭证 | R21: 108173712739
A22: 费用 | B22: 53001905038050548106 | C22: 云南溯源科技有限公司 | D22: 20260204 15:17:45 | E22: 500 | F22: 0 | G22: 612488.91 | H22: 人民币元 | I22: 中科视拓（南京）科技有限公司 | J22: 125916912310001 | K22: 招商银行股份有限公司南京星火路支行 | L22: 20260204 | M22: 电子转账 | N22: 服务费（ADL00354487） | O22: 13367-530905038EXW4669X9Y | Q22: 电子转账凭证 | R22: 108173712739
A23: 费用 | B23: 53001905038050548106 | C23: 云南溯源科技有限公司 | D23: 20260204 15:21:00 | E23: 4.5 | F23: 0 | G23: 612484.41 | H23: 人民币元 | L23: 20260204 | M23: 手续费 | N23: 对公人民币转账、汇款（含退汇）-跨行异地 | O23: 13368-530905038EZ5F6MY2CG | Q23: 电子转账凭证 | R23: 108173733635
A24: 费用 | B24: 53001905038050548106 | C24: 云南溯源科技有限公司 | D24: 20260204 15:21:00 | E24: 300 | F24: 0 | G24: 612184.41 | H24: 人民币元 | I24: 中科视拓（南京）科技有限公司 | J24: 125916912310001 | K24: 招商银行股份有限公司南京星火路支行 | L24: 20260204 | M24: 电子转账 | N24: 服务费（ADL00823854） | O24: 13369-530905038EZ5F6MY2CG | Q24: 电子转账凭证 | R24: 108173733635
A25: 费用 | B25: 53001905038050548106 | C25: 云南溯源科技有限公司 | D25: 20260204 15:22:29 | E25: 200 | F25: 0 | G25: 611984.41 | H25: 人民币元 | L25: 20260204 | M25: 企业网银服务费 | N25: 企业网银服务费（包年）补缴（共1期） | O25: 13370-530085036EZLXCM1UUB
A26: 费用 | B26: 53001905038050548106 | C26: 云南溯源科技有限公司 | D26: 20260204 15:27:01 | E26: 1 | F26: 0 | G26: 611983.41 | H26: 人民币元 | L26: 20260204 | M26: 手续费 | N26: 对公人民币转账、汇款（含退汇）-跨行同城 | O26: 13371-530905038F1A2T959F6 | Q26: 电子转账凭证 | R26: 108173769163
A27: 税款 | B27: 53001905038050548106 | C27: 云南溯源科技有限公司 | D27: 20260204 15:27:01 | E27: 2500 | F27: 0 | G27: 609483.41 | H27: 人民币元 | I27: 云南溯源科技有限公司 | J27: 2502014019350006386 | K27: 中国工商银行昆明北京路支行 | L27: 20260204 | M27: 电子转账 | N27: 税款 | O27: 13372-530905038F1A2T959F6 | Q27: 电子转账凭证 | R27: 108173769163
A28: 费用 | B28: 53001905038050548106 | C28: 云南溯源科技有限公司 | D28: 20260204 15:30:29 | E28: 1 | F28: 0 | G28: 609482.41 | H28: 人民币元 | L28: 20260204 | M28: 手续费 | N28: 对公人民币转账、汇款（含退汇）-跨行同城 | O28: 13373-530905038F2FZ2VSO8W | Q28: 电子转账凭证 | R28: 108173777396
A29: 公司帐户互转出 | B29: 53001905038050548106 | C29: 云南溯源科技有限公司 | D29: 20260204 15:30:29 | E29: 500000 | F29: 0 | G29: 109482.41 | H29: 人民币元 | I29: 云南溯源科技有限公司 | J29: 39610188000598826 | K29: 中国光大银行昆明分行营业部 | L29: 20260204 | M29: 电子转账 | N29: 本公司帐户 | O29: 13374-530905038F2FZ2VSO8W | Q29: 电子转账凭证 | R29: 108173777396
A30: 往来款收款 | B30: 53001905038050548106 | C30: 云南溯源科技有限公司 | D30: 20260204 17:07:45 | E30: 0 | F30: 100000 | G30: 209482.41 | H30: 人民币元 | I30: 贾小花 | J30: 6217003900007788112 | K30: 建行通海支行 | L30: 20260204 | M30: 转账存入 | N30: 暂借款 | O30: 13375-530085036GT8QNNMC90 | AM30: 53001905038050548106
A31: 往来款收款 | B31: 53001905038050548106 | C31: 云南溯源科技有限公司 | D31: 20260205 09:30:05 | E31: 0 | F31: 800000 | G31: 1009482.4 | H31: 人民币元 | I31: 云南瀚泞岚商贸有限公司 | J31: 135705991593 | K31: 中国银行股份有限公司昆明市科医路支行 | L31: 20260205 | M31: 电子汇入 | N31: 往来款 | O31: 13376-53008503695ODS2KAOR | Q31: 电汇凭证
A32: 费用 | B32: 53001905038050548106 | C32: 云南溯源科技有限公司 | D32: 20260206 09:19:03 | E32: 1 | F32: 0 | G32: 1009481.4 | H32: 人民币元 | L32: 20260206 | M32: 手续费 | N32: 对公人民币转账、汇款（含退汇）-跨行同城 | O32: 13377-53090503891RQQF03JR | Q32: 电子转账凭证 | R32: 108178394829
A33: 公司帐户互转出 | B33: 53001905038050548106 | C33: 云南溯源科技有限公司 | D33: 20260206 09:19:03 | E33: 300000 | F33: 0 | G33: 709481.41 | H33: 人民币元 | I33: 云南溯源科技有限公司 | J33: 39610188000598826 | K33: 中国光大银行昆明分行营业部 | L33: 20260206 | M33: 电子转账 | N33: 本公司帐户 | O33: 13378-53090503891RQQF03JR | Q33: 电子转账凭证 | R33: 108178394829
A34: 费用 | B34: 53001905038050548106 | C34: 云南溯源科技有限公司 | D34: 20260206 09:20:34 | E34: 1 | F34: 0 | G34: 709480.41 | H34: 人民币元 | L34: 20260206 | M34: 手续费 | N34: 对公人民币转账、汇款（含退汇）-跨行同城 | O34: 13379-530905038928GV5WB8P | Q34: 电子转账凭证 | R34: 108178398950
A35: 公司帐户互转出 | B35: 53001905038050548106 | C35: 云南溯源科技有限公司 | D35: 20260206 09:20:34 | E35: 400000 | F35: 0 | G35: 309480.41 | H35: 人民币元 | I35: 云南溯源科技有限公司 | J35: 39610188000598826 | K35: 中国光大银行昆明分行营业部 | L35: 20260206 | M35: 电子转账 | N35: 本公司帐户 | O35: 13380-530905038928GV5WB8P | Q35: 电子转账凭证 | R35: 108178398950
A36: 费用 | B36: 53001905038050548106 | C36: 云南溯源科技有限公司 | D36: 20260206 09:21:50 | E36: 1 | F36: 0 | G36: 309479.41 | H36: 人民币元 | L36: 20260206 | M36: 手续费 | N36: 对公人民币转账、汇款（含退汇）-跨行同城 | O36: 13381-53090503892N8ENLALH | Q36: 电子转账凭证 | R36: 108178397032
A37: 公司帐户互转出 | B37: 53001905038050548106 | C37: 云南溯源科技有限公司 | D37: 20260206 09:21:50 | E37: 300000 | F37: 0 | G37: 9479.41 | H37: 人民币元 | I37: 云南溯源科技有限公司 | J37: 39610188000598826 | K37: 中国光大银行昆明分行营业部 | L37: 20260206 | M37: 电子转账 | N37: 本公司帐户 | O37: 13382-53090503892N8ENLALH | Q37: 电子转账凭证 | R37: 108178397032
A38: 费用 | B38: 53001905038050548106 | C38: 云南溯源科技有限公司 | D38: 20260209 22:08:42 | E38: 10 | F38: 0 | G38: 9469.41 | H38: 人民币元 | L38: 20260209 | M38: 短信服务费 | N38: 短信服务费 | O38: 13383-530905038LQTIK5HJE7
A39: 往来款收款 | B39: 53001905038050548106 | C39: 云南溯源科技有限公司 | D39: 20260210 10:31:11 | E39: 0 | F39: 10000.48 | G39: 19469.89 | H39: 人民币元 | I39: 中招国际招标有限公司云南分公司 | J39: 2502124119024521401 | K39: 中国工商银行股份有限公司昆明花园支行 | L39: 20260210 | M39: 电子汇入 | N39: TC25970CS[202602]记-200 | O39: 13384-530085036A5HZKFNN09 | Q39: 电汇凭证
A40: 费用 | B40: 53001905038050548106 | C40: 云南溯源科技有限公司 | D40: 20260211 11:03:35 | E40: 35 | F40: 0 | G40: 19434.89 | H40: 人民币元 | I40: 中国电信股份有限公司昆明分公司 | J40: 2502013009022108588 | K40: 中国工商银行昆明护国支行 | L40: 20260211 | M40: 电子汇出 | N40: 电子汇出 | O40: 13385-530905038AV3U7MLXB2 | Q40: 电子转账凭证
A41: 费用 | B41: 53001905038050548106 | C41: 云南溯源科技有限公司 | D41: 20260211 11:05:33 | E41: 164 | F41: 0 | G41: 19270.89 | H41: 人民币元 | I41: 中国电信股份有限公司昆明分公司 | J41: 2502013009022108588 | K41: 中国工商银行昆明护国支行 | L41: 20260211 | M41: 电子汇出 | N41: 电子汇出 | O41: 13386-530905038AVT3N95F37 | Q41: 电子转账凭证
...

Sheet 光大2月
B1: 交易日期 | C1: 交易时间 | D1: 借方发生额 | E1: 贷方发生额 | F1: 账户余额 | G1: 对方名称 | H1: 对方账号 | I1: 摘要 | J1: 对方银行 | K1: 凭证号 | L1: 流水号
B3: 交易日期 | C3: 交易时间 | D3: 借方发生额 | E3: 贷方发生额 | F3: 账户余额 | G3: 对方名称 | H3: 对方账号 | I3: 摘要 | J3: 对方银行 | K3: 凭证号 | L3: 流水号
A5: 公司帐户互转入 | B5: 2026-02-03 | C5: 09:50:15 | E5: 500000 | F5: 517429.58 | G5: 云南溯源科技有限公司 | H5: 53001905038050548106 | I5: 本公司帐户 | J5: 中国建设银行股份有限公司昆明金实支行 | K5: 060 | L5: 901m63000405
A6: 公司帐户互转入 | B6: 2026-02-03 | C6: 09:53:23 | E6: 500000 | F6: 1017429.58 | G6: 云南溯源科技有限公司 | H6: 53001905038050548106 | I6: 本公司帐户 | J6: 中国建设银行股份有限公司昆明金实支行 | K6: 060 | L6: 901l12000461
A7: 公司帐户互转入 | B7: 2026-02-04 | C7: 15:08:22 | E7: 500000 | F7: 1517429.58 | G7: 云南溯源科技有限公司 | H7: 53001905038050548106 | I7: 本公司帐户 | J7: 中国建设银行股份有限公司昆明金实支行 | K7: 060 | L7: 901m63001698
A8: 公司帐户互转入 | B8: 2026-02-04 | C8: 15:30:42 | E8: 500000 | F8: 2017429.58 | G8: 云南溯源科技有限公司 | H8: 53001905038050548106 | I8: 本公司帐户 | J8: 中国建设银行股份有限公司昆明金实支行 | K8: 060 | L8: 901h98001775
A9: 公司帐户互转入 | B9: 2026-02-06 | C9: 09:19:09 | E9: 300000 | F9: 2317429.58 | G9: 云南溯源科技有限公司 | H9: 53001905038050548106 | I9: 本公司帐户 | J9: 中国建设银行股份有限公司昆明金实支行 | K9: 060 | L9: 901l16000314
A10: 公司帐户互转入 | B10: 2026-02-06 | C10: 09:20:38 | E10: 400000 | F10: 2717429.58 | G10: 云南溯源科技有限公司 | H10: 53001905038050548106 | I10: 本公司帐户 | J10: 中国建设银行股份有限公司昆明金实支行 | K10: 060 | L10: 901l09000305
A11: 公司帐户互转入 | B11: 2026-02-06 | C11: 09:22:07 | E11: 300000 | F11: 3017429.58 | G11: 云南溯源科技有限公司 | H11: 53001905038050548106 | I11: 本公司帐户 | J11: 中国建设银行股份有限公司昆明金实支行 | K11: 060 | L11: 901m62000320
A12: 往来款付款 | B12: 2026-02-09 | C12: 21:54:18 | D12: 3015208.3 | F12: 2221.25 | G12: 云南溯源科技有限公司 | H12: 396101830000001448174 | I12: 还贷[借据号=21302504005312001] | L12: 993961001031
A13: 往来款收款 | B13: 2026-02-13 | C13: 16:10:09 | E13: 3000000 | F13: 3002221.25 | G13: 云南溯源科技有限公司 | H13: 396101830000001586190 | I13: 一般贷款21302604001081001 | J13: 昆明分行 | L13: 901C35000023
A14: 工程服务费 | B14: 2026-02-13 | C14: 17:14:15 | D14: 46903.79 | F14: 2955317.46 | G14: 云南邦臣科技有限公司 | H14: 9550880209719900118 | I14: 工程服务费 | J14: 广发银行股份有限公司昆明第一支行 | L14: 901300048668
A15: 公司帐户互转出 | B15: 2026-02-13 | C15: 17:14:58 | D15: 38786.23 | F15: 2916531.23 | G15: 云南溯源科技有限公司 | H15: 2502014019350006386 | I15: 社保款 | J15: 中国工商银行昆明北京路支行 | L15: 901303048569
A16: 公司帐户互转出 | B16: 2026-02-13 | C16: 17:15:37 | D16: 184597.41 | F16: 2731933.82 | G16: 云南溯源科技有限公司 | H16: 53001905038050548106 | I16: 工资及过节费 | J16: 中国建设银行股份有限公司昆明金实支行 | L16: 901303048637
A17: 往来款付款 | B17: 2026-02-28 | C17: 09:34:00 | D17: 2087000 | F17: 644933.82 | G17: 昆明易格科技有限公司 | H17: 2502124109024506787 | I17: 货款 | J17: 中国工商银行股份有限公司昆明花园支行 | L17: 901139000050
A18: 往来款付款 | B18: 2026-02-28 | C18: 16:53:27 | D18: 150000 | F18: 494933.82 | G18: 昆明市盘龙区盛源软件开发服务部 | H18: 120871923040000000744 | I18: 技术服务费 | J18: 富滇银行股份有限公司昆明万华支行 | L18: 901313018678
A19: 往来款付款 | B19: 2026-02-28 | C19: 16:54:56 | D19: 163000 | F19: 331933.82 | G19: 威斯达昆明信息技术有限责任公司 | H19: 120871361010000006339 | I19: 服务费 | J19: 富滇银行股份有限公司昆明正义路支行 | L19: 901313018735
B22: 合计 | D22: =SUM(D2:D21) -> 5685495.8 | E22: =SUM(E2:E21) -> 6000000
A24: 货款 | D24: =SUMIF(A1:A21,A24,D1:D21) -> 0
A25: 工程服务费 | D25: =SUMIF(A1:A21,A25,D1:D21) -> 46903.79
A26: 费用 | D26: =SUMIF(A1:A21,A26,D1:D21) -> 0
A27: 税款 | D27: =SUMIF(A1:A21,A27,D1:D21) -> 0
A28: 薪资社保福利 | D28: =SUMIF(A1:A21,A28,D1:D21) -> 0
A29: 往来款付款 | D29: =SUMIF(A1:A21,A29,D1:D21) -> 5415208.3
A30: 备用金取现 | D30: =SUMIF(A1:A21,A30,D1:D21) -> 0
A31: 公司帐户互转出 | D31: =SUMIF(A1:A21,A31,D1:D21) -> 223383.64
B33: 合计 | D33: =SUM(SUM(D24:D31)) -> 5685495.8
D34: =D22-D33 -> 0
A36: 工程款收入 | E36: =SUMIF(A1:A21,A36,E1:E21) -> 0
A37: 销售货款收入 | E37: =SUMIF(A1:A21,A37,E1:E21) -> 0
A38: 其它收入 | E38: =SUMIF(A1:A21,A38,E1:E21) -> 0
A39: 往来款收款 | E39: =SUMIF(A1:A21,A39,E1:E21) -> 3000000
A40: 备用金存入 | E40: =SUMIF(A1:A21,A40,E1:E21) -> 0
A41: 公司帐户互转入 | E41: =SUMIF(A1:A21,A41,E1:E21) -> 3000000
B43: 合计 | E43: =SUM(E36:E41) -> 6000000
E44: =E43-E22 -> 0

Sheet 平安2月
B1: 交易时间 | C1: 账号 | D1: 币种 | E1: 收入 | F1: 支出 | G1: 冲正标志 | H1: 账户余额 | I1: 对方账号 | J1: 对方户名 | K1: 摘要 | L1: 交易用途 | M1: 对方账号开户网点行号 | N1: 对方账号开户行 | O1: 交易码 | P1: 业务流水号 | Q1: 交易流水号 | R1: 主机流水号 | S1: 单位结算卡卡号 | T1: 交易日期
A2: 费用 | B2: 20260201011512 | C2: 15990259060093 | D2: RMB | F2: 6458.33 | G2: _ | H2: 3274.89 | I2: 4031544 | J2: 小企业与腾龙核心系统间往来 | K2: 贷款扣款 | L2: 批量还款 | M2: 9998 | N2: 平安银行 | O2: G1009L2 | P2: 0162802602015220311564 | Q2: 0162802602015220311564 | R2: 0164612602010011229933 | T2: 20260201 | U2: 016461260201001122993300000001
A3: 费用 | B3: 20260201055130 | C3: 15990259060093 | D3: RMB | F3: 1 | G3: _ | H3: 3273.89 | I3: 5103117 | J3: 对公金卫士手续费收入 | K3: 金卫士 | M3: 0660 | N3: 平安银行昆明分行 | O3: M7046L2 | P3: 1428062602010235788358 | Q3: 1428062602010235788358 | R3: 0164612602010031348641 | T3: 20260201 | U3: 016461260201003134864100000001
A4: 公司帐户互转入 | B4: 20260227143751 | C4: 15990259060093 | D4: RMB | E4: 6000 | G4: - | H4: 9273.89 | I4: 53001905038050548106 | J4: 云南溯源科技有限公司 | K4: 跨行转账 | L4: 本公司帐户 | M4: 105731004103 | N4: 中国建设银行股份有限公司昆明金实支行 | O4: G1001 | P4: 0121222602274484401842 | Q4: 0121222602277146530431 | R4: 0164612602270134883749 | T4: 20260227 | U4: 016461260227013488374900000001
B8: 合计 | E8: =SUM(E2:E7) -> 6000 | F8: =SUM(F2:F7) -> 6459.33
A10: 货款 | C10: =SUMIF(A2:A7,A10,F2:F7) -> 0
A11: 工程服务费 | C11: =SUMIF(A1:A7,A11,E2:E7) -> 0
A12: 费用 | C12: =SUMIF(A2:A7,A12,F2:F7) -> 6459.33
A13: 税款 | C13: =SUMIF(A2:A7,A13,F2:F7) -> 0
A14: 薪资社保福利 | C14: =SUMIF(A2:A7,A14,F2:F7) -> 0
A15: 往来款付款 | C15: =SUMIF(A2:A7,A15,F2:F7) -> 0
A16: 备用金取现 | C16: =SUMIF(A2:A7,A16,E2:E7) -> 0
A17: 公司帐户互转出 | C17: =SUMIF(A2:A7,A17,F2:F7) -> 0
B19: 合计 | C19: =SUM(SUM(C10:C17)) -> 6459.33
C20: =F8-C19 -> 0
A22: 工程款收入 | C22: =SUMIF(A2:A7,A22,E2:E7) -> 0
A23: 销售货款收入 | C23: =SUMIF(A2:A7,A23,E2:E7) -> 0
A24: 其它收入 | C24: =SUMIF(A2:A7,A24,E2:E7) -> 0
A25: 往来款收款 | C25: =SUMIF(A2:A7,A25,E2:E7) -> 0
A26: 公司帐户互转入 | C26: =SUMIF(A2:A7,A26,E2:E7) -> 6000
B27: 合计 | C27: =SUM(C22:C26) -> 6000
C28: =C27-E8 -> 0

Sheet 民生2月
B1: 交易时间 | C1: 摘要 | D1: 凭证类型 | E1: 凭证号 | F1: 借方发生额 | G1: 贷方发生额 | H1: 账户余额 | I1: 流水号 | J1: 对方户名/账号 | K1: 对方行名
A3: 往来款收款 | B3: 2026/02/03 10:21:33 | C3: 放款 | F3: 0 | G3: 1000000 | H3: 1005254.1 | I3: 35420202602032105547006 | J3: LN2211202691627495
A4: 往来款付款 | B4: 2026/02/03 16:14:11 | C4: 货款 | D4: 网银凭证 | E4: 00000038 | F4: 100000 | G4: 0 | H4: 905254.14 | I4: 31300202602030685938667 | J4: 云南科裕腾科技有限责任公司/9140420102000037 | K4: 富滇银行股份有限公司
A5: 费用 | B5: 2026/02/03 16:14:11 | C5: 手续费 | F5: 8 | G5: 0 | H5: 905246.14 | I5: 31300202602030685938667 | J5: 2211-C070470 | K5: 中国民生银行股份有限公司昆明西园路支行
A6: 往来款付款 | B6: 2026/02/03 17:08:52 | C6: 货款 | D6: 网银凭证 | E6: 00000039 | F6: 420000 | G6: 0 | H6: 485246.14 | I6: 31300202602030686029576 | J6: 云南科裕腾科技有限责任公司/9140420102000037 | K6: 富滇银行股份有限公司
A7: 费用 | B7: 2026/02/03 17:08:52 | C7: 手续费 | F7: 12 | G7: 0 | H7: 485234.14 | I7: 31300202602030686029576 | J7: 2211-C070470 | K7: 中国民生银行股份有限公司昆明西园路支行
A8: 往来款付款 | B8: 2026/02/03 17:12:37 | C8: 货款 | D8: 网银凭证 | E8: 00000040 | F8: 480000 | G8: 0 | H8: 5234.14 | I8: 31300202602030686035470 | J8: 云南科裕腾科技有限责任公司/9140420102000037 | K8: 富滇银行股份有限公司
A9: 费用 | B9: 2026/02/03 17:12:37 | C9: 手续费 | F9: 12 | G9: 0 | H9: 5222.14 | I9: 31300202602030686035470 | J9: 2211-C070470 | K9: 中国民生银行股份有限公司昆明西园路支行
B14: 合计 | F14: =SUM(F2:F13) -> 1000032 | G14: =SUM(G2:G13) -> 1000000
A16: 货款 | D16: =SUMIF(A1:A13,A16,F1:F13) -> 0
A17: 工程服务费 | D17: =SUMIF(A1:A13,A17,F1:F13) -> 0
A18: 费用 | D18: =SUMIF(A1:A13,A18,F1:F13) -> 32
A19: 税款 | D19: =SUMIF(A1:A13,A19,F1:F13) -> 0
A20: 薪资社保福利 | D20: =SUMIF(A1:A13,A20,D1:D13) -> 0
A21: 往来款付款 | D21: =SUMIF(A1:A13,A21,F1:F13) -> 1000000
A22: 备用金取现 | D22: =SUMIF(A1:A13,A22,F1:F13) -> 0
A23: 公司帐户互转出 | D23: =SUMIF(A1:A13,A23,F1:F13) -> 0
B25: 合计 | D25: =SUM(SUM(D16:D24)) -> 1000032
D26: =F14-D25 -> 0
A28: 工程款收入 | D28: =SUMIF(A1:A13,A28,G1:G13) -> 0
A29: 销售货款收入 | D29: =SUMIF(A1:A13,A29,G1:G13) -> 0
A30: 其它收入 | D30: =SUMIF(A1:A13,A30,G1:G13) -> 0
A31: 往来款收款 | D31: =SUMIF(A1:A13,A31,G1:G13) -> 1000000
A32: 公司帐户互转入 | D32: =SUMIF(A1:A13,A32,G1:G13) -> 0
B34: 合计 | D34: =SUM(D28:D33) -> 1000000
D35: =D34-G14 -> 0

Sheet 工行税户2月
A1: 凭证号 | B1: 交易时间 | C1: 对方单位 | D1: 对方行名 | E1: 对方账号 | F1: 转入金额 | G1: 转出金额 | H1: 余额 | I1: 用途 | J1: 摘要 | K1: 附言
A3: 薪资社保福利 | B3: 2026-02-14 12:04:14 | C3: 待报解预算收入 | D3: 中国工商银行 | E3: 2502010011200310097 | G3: 38786.23 | H3: 2487.41 | I3: 代理国库税收收缴 | J3: 代理国库税收收缴 | K3: 22387386
A4: 薪资社保福利 | B4: 2026-02-14 11:39:53 | C4: 待报解预算收入 | D4: 中国工商银行 | E4: 2502010011200310097 | G4: 1431.27 | H4: 41273.64 | I4: 代理国库税收收缴 | J4: 代理国库税收收缴 | K4: 22386867
A5: 公司帐户互转入 | B5: 2026-02-13 17:15:05 | C5: 云南溯源科技有限公司 | D5: 中国光大银行昆明分行营业部 | E5: 39610188000598826 | F5: 38786.23 | H5: 42704.91 | J5: 社保款 | K5: 社保款
A6: 税款 | B6: 2026-02-13 16:59:49 | C6: 待报解预算收入 | D6: 中国工商银行 | E6: 2502010011200310097 | G6: 719.32 | H6: 3918.68 | I6: 代理国库税收收缴 | J6: 代理国库税收收缴 | K6: 22037956
A7: 公司帐户互转入 | B7: 2026-02-04 15:27:13 | C7: 云南溯源科技有限公司 | D7: 中国建设银行股份有限公司昆明金实支行 | E7: 53001905038050548106 | F7: 2500 | H7: 4638 | J7: 税款 | K7: 税款
B9: 合计 | F9: =SUM(F1:F8) -> 41286.23 | G9: =SUM(G1:G8) -> 40936.82
A11: 货款 | C11: =SUMIF(A1:A8,A11,G1:G8) -> 0
A12: 工程服务费 | C12: =SUMIF(A1:A8,A12,G1:G8) -> 0
A13: 费用 | C13: =SUMIF(A1:A8,A13,G1:G8) -> 0
A14: 税款 | C14: =SUMIF(A1:A8,A14,G1:G8) -> 719.32
A15: 薪资社保福利 | C15: =SUMIF(A1:A8,A15,G1:G8) -> 40217.5
A16: 往来款付款 | C16: =SUMIF(A1:A8,A16,G1:G8) -> 0
A17: 备用金取现 | C17: =SUMIF(A1:A8,A17,G1:G8) -> 0
A18: 公司帐户互转出 | C18: =SUMIF(A1:A8,A18,G1:G8) -> 0
B20: 合计 | C20: =SUM(SUM(C11:C19)) -> 40936.82
C21: =C20-G9 -> 0
A23: 工程款收入 | C23: =SUMIF(A1:A8,A23,F1:F8) -> 0
A24: 销售货款收入 | C24: =SUMIF(A1:A8,A24,F1:F8) -> 0
A25: 其它收入 | C25: =SUMIF(A1:A8,A25,F1:F8) -> 0
A26: 往来款收款 | C26: =SUMIF(A1:A8,A26,F1:F8) -> 0
A27: 公司帐户互转入 | C27: =SUMIF(A1:A8,A27,F1:F8) -> 41286.23
B29: 合计 | C29: =SUM(C23:C28) -> 41286.23
C30: =C29-F9 -> 0
